Workbook

Sheet Org Setup
A1: EUI-64 | B1: DUIS Role | C1: MPID | D1: DUIS Version | E1: Environment | F1: XMLSigningCert | G1: GBCS DS | H1: GBCS DS Base 64 | I1: GBCS DS Subject Key Identifier | J1: GBCS KA | K1: GBCS KA Base 64 | L1: GBCS KA Subject Key Identifier | M1: GBCS PPKA | N1: GBCS PPKA Base 64 | O1: GBCS PPKA Subject Key Identifier | P1: ADT File | Q1: EUCT / Subset Testing Complete
A2: 70-B3-D5-1F-31-AA-01-00 | B2: IS (1) | C2: HCLT | D2: 3 | E2: SIT-A
A3: 70-B3-D5-1F-31-AA-01-01 | B3: IS (2) | C3: HCLT | D3: 3 | E3: SIT-A
A4: 70-B3-D5-1F-31-AA-01-02 | B4: ES | C4: HCLT | D4: 3 | E4: SIT-A | G4: N/A | H4: N/A | M4: N/A | N4: N/A | P4: Not Required
A5: 70-B3-D5-1F-31-AA-01-03 | B5: GS (1) | C5: HCL | D5: 3 | E5: SIT-A
A6: 70-B3-D5-1F-31-AA-01-04 | B6: GS (2) | C6: HCL | D6: 3 | E6: SIT-A
A7: 70-B3-D5-1F-31-AA-01-05 | B7: ED | C7: HCLT | D7: 3 | E7: SIT-A | M7: N/A | N7: N/A
A8: 70-B3-D5-1F-31-AA-01-06 | B8: GT | C8: HCL | D8: 3 | E8: SIT-A | M8: N/A | N8: N/A
A9: 70-B3-D5-1F-31-AA-01-07 | B9: RSA | C9: HCLT, HCL | D9: 3 | E9: SIT-A | G9: N/A | H9: N/A | M9: N/A | N9: N/A | P9: Not Required
A10: 70-B3-D5-1F-31-AA-01-08 | B10: OU | D10: 3 | E10: SIT-A | G10: N/A | H10: N/A | M10: N/A | N10: N/A | P10: Not Required
A11: 70-B3-D5-1F-31-AA-01-09 | B11: IS (1) | C11: HCLT | D11: 3.1 | E11: SIT-A
A12: 70-B3-D5-1F-31-AA-01-10 | B12: IS (2) | C12: HCLT | D12: 3.1 | E12: SIT-A
A13: 70-B3-D5-1F-31-AA-01-11 | B13: ES | C13: HCLT | D13: 3.1 | E13: SIT-A | G13: N/A | H13: N/A | M13: N/A | N13: N/A | P13: Not Required
A14: 70-B3-D5-1F-31-AA-01-12 | B14: GS (1) | C14: HCL | D14: 3.1 | E14: SIT-A
A15: 70-B3-D5-1F-31-AA-01-13 | B15: GS (2) | C15: HCL | D15: 3.1 | E15: SIT-A
A16: 70-B3-D5-1F-31-AA-01-14 | B16: ED | C16: HCLT | D16: 3.1 | E16: SIT-A | M16: N/A | N16: N/A
A17: 70-B3-D5-1F-31-AA-01-15 | B17: GT | C17: HCL | D17: 3.1 | E17: SIT-A | M17: N/A | N17: N/A
A18: 70-B3-D5-1F-31-AA-01-16 | B18: RSA | C18: HCLT, HCL | D18: 3.1 | E18: SIT-A | G18: N/A | H18: N/A | M18: N/A | N18: N/A | P18: Not Required
A19: 70-B3-D5-1F-31-AA-01-17 | B19: OU | D19: 3.1 | E19: SIT-A | G19: N/A | H19: N/A | M19: N/A | N19: N/A | P19: Not Required
A20: 70-B3-D5-1F-31-AA-01-18 | B20: IS (1) | C20: HCLT | D20: 4 | E20: SIT-A
A21: 70-B3-D5-1F-31-AA-01-19 | B21: IS (2) | C21: HCLT | D21: 4 | E21: SIT-A
A22: 70-B3-D5-1F-31-AA-01-20 | B22: ES | C22: HCLT | D22: 4 | E22: SIT-A | G22: N/A | H22: N/A | M22: N/A | N22: N/A | P22: Not Required
A23: 70-B3-D5-1F-31-AA-01-21 | B23: GS (1) | C23: HCL | D23: 4 | E23: SIT-A
A24: 70-B3-D5-1F-31-AA-01-22 | B24: GS (2) | C24: HCL | D24: 4 | E24: SIT-A
A25: 70-B3-D5-1F-31-AA-01-23 | B25: ED | C25: HCLT | D25: 4 | E25: SIT-A | M25: N/A | N25: N/A
A26: 70-B3-D5-1F-31-AA-01-24 | B26: GT | C26: HCL | D26: 4 | E26: SIT-A | M26: N/A | N26: N/A
A27: 70-B3-D5-1F-31-AA-01-25 | B27: RSA | C27: HCLT, HCL | D27: 4 | E27: SIT-A | G27: N/A | H27: N/A | M27: N/A | N27: N/A | P27: Not Required
A28: 70-B3-D5-1F-31-AA-01-26 | B28: OU | D28: 4 | E28: SIT-A | G28: N/A | H28: N/A | M28: N/A | N28: N/A | P28: Not Required
A29: 70-B3-D5-1F-31-AA-01-27 | B29: IS (1) | C29: HCLT | D29: 5 | E29: SIT-A
A30: 70-B3-D5-1F-31-AA-01-28 | B30: IS (2) | C30: HCLT | D30: 5 | E30: SIT-A
A31: 70-B3-D5-1F-31-AA-01-29 | B31: ES | C31: HCLT | D31: 5 | E31: SIT-A | G31: N/A | H31: N/A | M31: N/A | N31: N/A | P31: Not Required
A32: 70-B3-D5-1F-31-AA-01-30 | B32: GS (1) | C32: HCL | D32: 5 | E32: SIT-A
A33: 70-B3-D5-1F-31-AA-01-31 | B33: GS (2) | C33: HCL | D33: 5 | E33: SIT-A
A34: 70-B3-D5-1F-31-AA-01-32 | B34: ED | C34: HCLT | D34: 5 | E34: SIT-A | M34: N/A | N34: N/A
A35: 70-B3-D5-1F-31-AA-01-33 | B35: GT | C35: HCL | D35: 5 | E35: SIT-A | M35: N/A | N35: N/A
A36: 70-B3-D5-1F-31-AA-01-34 | B36: RSA | C36: HCLT, HCL | D36: 5 | E36: SIT-A | G36: N/A | H36: N/A | M36: N/A | N36: N/A | P36: Not Required
A37: 70-B3-D5-1F-31-AA-01-35 | B37: OU | D37: 5 | E37: SIT-A | G37: N/A | H37: N/A | M37: N/A | N37: N/A | P37: Not Required
A38: 70-B3-D5-1F-31-AA-01-36 | B38: IS (1) | C38: HCLT | D38: 5.1 | E38: SIT-A
A39: 70-B3-D5-1F-31-AA-01-37 | B39: IS (2) | C39: HCLT | D39: 5.1 | E39: SIT-A
A40: 70-B3-D5-1F-31-AA-01-38 | B40: ES | C40: HCLT | D40: 5.1 | E40: SIT-A | G40: N/A | H40: N/A | M40: N/A | N40: N/A | P40: Not Required
...

Sheet MPAN Data
A1: MPAN | B1: Count | C1: Environment | D1: Current Supplier Association | E1: DUIS Role | F1: DUIS Version | G1: Device GUID | H1: Meter Set Name
A2: 2200041044971 | B2: =COUNTIF(A$2:A$411,A2) -> 1 | C2: UIT-B | D2: 70-B3-D5-1F-31-AA-04-38 | E2: =VLOOKUP(D2,'Org Setup'!A:B,2,0) -> ES | F2: =VLOOKUP(D2,'Org Setup'!A:D,4,0) -> 5.1
A3: 2200041044243 | B3: =COUNTIF(A$2:A$411,A3) -> 1 | C3: UIT-B | D3: 70-B3-D5-1F-31-AA-04-38 | E3: =VLOOKUP(D3,'Org Setup'!A:B,2,0) -> ES | F3: =VLOOKUP(D3,'Org Setup'!A:D,4,0) -> 5.1
A4: 2200040683523 | B4: =COUNTIF(A$2:A$411,A4) -> 1 | C4: UIT-B | D4: 70-B3-D5-1F-31-AA-04-36 | E4: =VLOOKUP(D4,'Org Setup'!A:B,2,0) -> IS (1) | F4: =VLOOKUP(D4,'Org Setup'!A:D,4,0) -> 5.1 | G4: H-DTAF-046-UB
A5: 2200040683505 | B5: =COUNTIF(A$2:A$411,A5) -> 1 | C5: UIT-B | D5: 70-B3-D5-1F-31-AA-04-36 | E5: =VLOOKUP(D5,'Org Setup'!A:B,2,0) -> IS (1) | F5: =VLOOKUP(D5,'Org Setup'!A:D,4,0) -> 5.1 | G5: 00-1D-24-02-01-16-63-A5 | H5: H-DTAF-031-UB
A6: 2200040683277 | B6: =COUNTIF(A$2:A$411,A6) -> 1 | C6: UIT-B | D6: 70-B3-D5-1F-31-AA-04-38 | E6: =VLOOKUP(D6,'Org Setup'!A:B,2,0) -> ES | F6: =VLOOKUP(D6,'Org Setup'!A:D,4,0) -> 5.1 | G6: 98-B1-77-FF-FF-50-DF-4B
A7: 2200023876953 | B7: =COUNTIF(A$2:A$411,A7) -> 1 | C7: UIT-B | D7: 70-B3-D5-1F-31-AA-04-38 | E7: =VLOOKUP(D7,'Org Setup'!A:B,2,0) -> ES | F7: =VLOOKUP(D7,'Org Setup'!A:D,4,0) -> 5.1
A8: 2200023649121 | B8: =COUNTIF(A$2:A$411,A8) -> 1 | C8: UIT-B | D8: 70-B3-D5-1F-31-AA-04-36 | E8: =VLOOKUP(D8,'Org Setup'!A:B,2,0) -> IS (1) | F8: =VLOOKUP(D8,'Org Setup'!A:D,4,0) -> 5.1 | G8: 1C-23-4F-00-00-04-37-15 | H8: H-DTAF-050-UB
A9: 2200023467563 | B9: =COUNTIF(A$2:A$411,A9) -> 1 | C9: UIT-B | D9: 70-B3-D5-1F-31-AA-04-38 | E9: =VLOOKUP(D9,'Org Setup'!A:B,2,0) -> ES | F9: =VLOOKUP(D9,'Org Setup'!A:D,4,0) -> 5.1
A10: 2200023373560 | B10: =COUNTIF(A$2:A$411,A10) -> 1 | C10: UIT-B | D10: 70-B3-D5-1F-31-AA-04-38 | E10: =VLOOKUP(D10,'Org Setup'!A:B,2,0) -> ES | F10: =VLOOKUP(D10,'Org Setup'!A:D,4,0) -> 5.1 | G10: 98-B1-77-FF-FF-50-DF-00
A11: 2200022873367 | B11: =COUNTIF(A$2:A$411,A11) -> 1 | C11: UIT-B | D11: 70-B3-D5-1F-31-AA-04-36 | E11: =VLOOKUP(D11,'Org Setup'!A:B,2,0) -> IS (1) | F11: =VLOOKUP(D11,'Org Setup'!A:D,4,0) -> 5.1 | G11: 98-B1-77-FF-FF-36-D0-E1 | H11: H-DTAF-048-UB
A12: 2200021898741 | B12: =COUNTIF(A$2:A$411,A12) -> 1 | C12: UIT-B | D12: 70-B3-D5-1F-31-AA-04-38 | E12: =VLOOKUP(D12,'Org Setup'!A:B,2,0) -> ES | F12: =VLOOKUP(D12,'Org Setup'!A:D,4,0) -> 5.1
A13: 2200021745799 | B13: =COUNTIF(A$2:A$411,A13) -> 1 | C13: UIT-B | D13: 70-B3-D5-1F-31-AA-04-36 | E13: =VLOOKUP(D13,'Org Setup'!A:B,2,0) -> IS (1) | F13: =VLOOKUP(D13,'Org Setup'!A:D,4,0) -> 5.1 | G13: 98-B1-77-FF-FF-36-F8-4A | H13: H-DTAF-034-UB
A14: 2200021384988 | B14: =COUNTIF(A$2:A$411,A14) -> 1 | C14: UIT-B | D14: 70-B3-D5-1F-31-AA-04-36 | E14: =VLOOKUP(D14,'Org Setup'!A:B,2,0) -> IS (1) | F14: =VLOOKUP(D14,'Org Setup'!A:D,4,0) -> 5.1 | G14: 00-1D-24-02-01-16-63-A3 | H14: H-DTAF-051-UB
A15: 2200020312779 | B15: =COUNTIF(A$2:A$411,A15) -> 1 | C15: UIT-B | D15: 70-B3-D5-1F-31-AA-04-38 | E15: =VLOOKUP(D15,'Org Setup'!A:B,2,0) -> ES | F15: =VLOOKUP(D15,'Org Setup'!A:D,4,0) -> 5.1
A16: 2200020312157 | B16: =COUNTIF(A$2:A$411,A16) -> 1 | C16: UIT-B | D16: 70-B3-D5-1F-31-AA-04-36 | E16: =VLOOKUP(D16,'Org Setup'!A:B,2,0) -> IS (1) | F16: =VLOOKUP(D16,'Org Setup'!A:D,4,0) -> 5.1 | G16: 00-1D-24-02-01-16-63-A8 | H16: H-DTAF-052-UB
A17: 2200020312120 | B17: =COUNTIF(A$2:A$411,A17) -> 1 | C17: UIT-B | D17: 70-B3-D5-1F-31-AA-04-36 | E17: =VLOOKUP(D17,'Org Setup'!A:B,2,0) -> IS (1) | F17: =VLOOKUP(D17,'Org Setup'!A:D,4,0) -> 5.1 | G17: 98-B1-77-FF-FF-36-D0-A1 | H17: H-DTAF-049-UB
A18: 2200019493881 | B18: =COUNTIF(A$2:A$411,A18) -> 1 | C18: UIT-B | D18: 70-B3-D5-1F-31-AA-04-38 | E18: =VLOOKUP(D18,'Org Setup'!A:B,2,0) -> ES | F18: =VLOOKUP(D18,'Org Setup'!A:D,4,0) -> 5.1
A19: 2200019493482 | B19: =COUNTIF(A$2:A$411,A19) -> 1 | C19: UIT-B | D19: 70-B3-D5-1F-31-AA-04-38 | E19: =VLOOKUP(D19,'Org Setup'!A:B,2,0) -> ES | F19: =VLOOKUP(D19,'Org Setup'!A:D,4,0) -> 5.1
A20: 2200019439607 | B20: =COUNTIF(A$2:A$411,A20) -> 1 | C20: UIT-B | D20: 70-B3-D5-1F-31-AA-04-36 | E20: =VLOOKUP(D20,'Org Setup'!A:B,2,0) -> IS (1) | F20: =VLOOKUP(D20,'Org Setup'!A:D,4,0) -> 5.1 | G20: 1C-23-4F-00-00-03-EB-BC | H20: H-DTAF-053-UB
A21: 2200019439582 | B21: =COUNTIF(A$2:A$411,A21) -> 1 | C21: UIT-B | D21: 70-B3-D5-1F-31-AA-04-36 | E21: =VLOOKUP(D21,'Org Setup'!A:B,2,0) -> IS (1) | F21: =VLOOKUP(D21,'Org Setup'!A:D,4,0) -> 5.1 | G21: 00-1D-24-02-01-30-96-51 | H21: H-DTAF-093-UB
A22: 2200019154030 | B22: =COUNTIF(A$2:A$411,A22) -> 1 | C22: UIT-B | D22: 70-B3-D5-1F-31-AA-04-36 | E22: =VLOOKUP(D22,'Org Setup'!A:B,2,0) -> IS (1) | F22: =VLOOKUP(D22,'Org Setup'!A:D,4,0) -> 5.1 | G22: 00-1D-24-02-01-1B-22-4D | H22: H-DTAF-100-UB
A23: 2200019066819 | B23: =COUNTIF(A$2:A$411,A23) -> 1 | C23: UIT-B | D23: 70-B3-D5-1F-31-AA-04-36 | E23: =VLOOKUP(D23,'Org Setup'!A:B,2,0) -> IS (1) | F23: =VLOOKUP(D23,'Org Setup'!A:D,4,0) -> 5.1
A24: 2200018610210 | B24: =COUNTIF(A$2:A$411,A24) -> 1 | C24: UIT-B | D24: 70-B3-D5-1F-31-AA-04-36 | E24: =VLOOKUP(D24,'Org Setup'!A:B,2,0) -> IS (1) | F24: =VLOOKUP(D24,'Org Setup'!A:D,4,0) -> 5.1
A25: 2200018525247 | B25: =COUNTIF(A$2:A$411,A25) -> 1 | C25: UIT-B | D25: 70-B3-D5-1F-31-AA-04-36 | E25: =VLOOKUP(D25,'Org Setup'!A:B,2,0) -> IS (1) | F25: =VLOOKUP(D25,'Org Setup'!A:D,4,0) -> 5.1
A26: 2200018261992 | B26: =COUNTIF(A$2:A$411,A26) -> 1 | C26: UIT-B | D26: 70-B3-D5-1F-31-AA-04-38 | E26: =VLOOKUP(D26,'Org Setup'!A:B,2,0) -> ES | F26: =VLOOKUP(D26,'Org Setup'!A:D,4,0) -> 5.1
A27: 2200017850818 | B27: =COUNTIF(A$2:A$411,A27) -> 1 | C27: UIT-B | D27: 70-B3-D5-1F-31-AA-04-38 | E27: =VLOOKUP(D27,'Org Setup'!A:B,2,0) -> ES | F27: =VLOOKUP(D27,'Org Setup'!A:D,4,0) -> 5.1
A28: 2200017806891 | B28: =COUNTIF(A$2:A$411,A28) -> 1 | C28: UIT-B | D28: 70-B3-D5-1F-31-AA-04-36 | E28: =VLOOKUP(D28,'Org Setup'!A:B,2,0) -> IS (1) | F28: =VLOOKUP(D28,'Org Setup'!A:D,4,0) -> 5.1
A29: 2200016368910 | B29: =COUNTIF(A$2:A$411,A29) -> 1 | C29: UIT-B | D29: 70-B3-D5-1F-31-AA-04-36 | E29: =VLOOKUP(D29,'Org Setup'!A:B,2,0) -> IS (1) | F29: =VLOOKUP(D29,'Org Setup'!A:D,4,0) -> 5.1 | G29: 98-B1-77-FF-FF-50-DE-DB | H29: H-DTAF-012-UB
A30: 2200016368895 | B30: =COUNTIF(A$2:A$411,A30) -> 1 | C30: UIT-B | D30: 70-B3-D5-1F-31-AA-04-38 | E30: =VLOOKUP(D30,'Org Setup'!A:B,2,0) -> ES | F30: =VLOOKUP(D30,'Org Setup'!A:D,4,0) -> 5.1
A31: 2200015982762 | B31: =COUNTIF(A$2:A$411,A31) -> 1 | C31: UIT-B | D31: 70-B3-D5-1F-31-AA-04-36 | E31: =VLOOKUP(D31,'Org Setup'!A:B,2,0) -> IS (1) | F31: =VLOOKUP(D31,'Org Setup'!A:D,4,0) -> 5.1 | G31: 98-B1-77-FF-FF-50-DF-00 | H31: H-DTAF-004-UB
A32: 2200015982498 | B32: =COUNTIF(A$2:A$411,A32) -> 1 | C32: UIT-B | D32: 70-B3-D5-1F-31-AA-04-36 | E32: =VLOOKUP(D32,'Org Setup'!A:B,2,0) -> IS (1) | F32: =VLOOKUP(D32,'Org Setup'!A:D,4,0) -> 5.1
A33: 2200014865245 | B33: =COUNTIF(A$2:A$411,A33) -> 1 | C33: UIT-B | D33: 70-B3-D5-1F-31-AA-04-36 | E33: =VLOOKUP(D33,'Org Setup'!A:B,2,0) -> IS (1) | F33: 5.3 | G33: 98-B1-77-FF-FF-50-DF-01 | H33: H-DTAF-030-UB | I33: Has ACB certs
A34: 2200014373954 | B34: =COUNTIF(A$2:A$411,A34) -> 1 | C34: UIT-B | D34: 70-B3-D5-1F-31-AA-04-36 | E34: =VLOOKUP(D34,'Org Setup'!A:B,2,0) -> IS (1) | F34: =VLOOKUP(D34,'Org Setup'!A:D,4,0) -> 5.1
A35: 2200013654746 | B35: =COUNTIF(A$2:A$411,A35) -> 1 | C35: UIT-B | D35: 70-B3-D5-1F-31-AA-04-36 | E35: =VLOOKUP(D35,'Org Setup'!A:B,2,0) -> IS (1) | F35: =VLOOKUP(D35,'Org Setup'!A:D,4,0) -> 5.1
A36: 2200013609390 | B36: =COUNTIF(A$2:A$411,A36) -> 1 | C36: UIT-B | D36: 70-B3-D5-1F-31-AA-04-36 | E36: =VLOOKUP(D36,'Org Setup'!A:B,2,0) -> IS (1) | F36: 4 | G36: 98-B1-77-FF-FF-50-DF-22 | H36: H-DTAF-019-UB | I36: This has certs for 04-36 in Device. | J36: E4 when sending 6.23
A37: 2200013580369 | B37: =COUNTIF(A$2:A$411,A37) -> 1 | C37: UIT-B | D37: 70-B3-D5-1F-31-AA-04-36 | E37: =VLOOKUP(D37,'Org Setup'!A:B,2,0) -> IS (1) | F37: =VLOOKUP(D37,'Org Setup'!A:D,4,0) -> 5.1
A38: 2200012999851 | B38: =COUNTIF(A$2:A$411,A38) -> 1 | C38: UIT-B | D38: 70-B3-D5-1F-31-AA-04-36 | E38: =VLOOKUP(D38,'Org Setup'!A:B,2,0) -> IS (1) | F38: =VLOOKUP(D38,'Org Setup'!A:D,4,0) -> 5.1
A39: 2200012654008 | B39: =COUNTIF(A$2:A$411,A39) -> 1 | C39: UIT-B | D39: 70-B3-D5-1F-31-AA-04-36 | E39: =VLOOKUP(D39,'Org Setup'!A:B,2,0) -> IS (1) | F39: =VLOOKUP(D39,'Org Setup'!A:D,4,0) -> 5.1
A40: 2200011409163 | B40: =COUNTIF(A$2:A$411,A40) -> 1 | C40: UIT-B | D40: 70-B3-D5-1F-31-AA-04-36 | E40: =VLOOKUP(D40,'Org Setup'!A:B,2,0) -> IS (1) | F40: =VLOOKUP(D40,'Org Setup'!A:D,4,0) -> 5.1
...

Sheet MPRN Data
A1: MPRN | B1: COUNT | C1: Environment | D1: Current Supplier Association | E1: DUIS Role | F1: DUIS Version | G1: Device GUID | H1: Meterset Name
A2: 8840678400 | B2: =COUNTIF(A$2:A$211,A2) -> 1 | C2: UIT-A | D2: 70-B3-D5-1F-31-AA-03-39 | E2: =VLOOKUP(D2,'Org Setup'!A:B,2,0) -> GS (1) | F2: =VLOOKUP(D2,'Org Setup'!A:D,4,0) -> 5.1 | G2: 90-4D-C3-00-00-14-C0-CE | H2: H-DTAF-101-UA
A3: 7454590409 | B3: =COUNTIF(A$2:A$211,A3) -> 1 | C3: UIT-B | D3: 70-B3-D5-1F-31-AA-04-39 | E3: =VLOOKUP(D3,'Org Setup'!A:B,2,0) -> GS (1) | F3: =VLOOKUP(D3,'Org Setup'!A:D,4,0) -> 5.1 | G3: 90-4D-C3-00-00-10-45-D4 | H3: H-DTAF-027-UB
A4: 7454577709 | B4: =COUNTIF(A$2:A$211,A4) -> 1 | C4: UIT-B | D4: 70-B3-D5-1F-31-AA-04-39 | E4: =VLOOKUP(D4,'Org Setup'!A:B,2,0) -> GS (1) | F4: =VLOOKUP(D4,'Org Setup'!A:D,4,0) -> 5.1 | G4: 44-11-02-00-00-20-EB-A5 | H4: H-DTAF-002-UB
A5: 7454574501 | B5: =COUNTIF(A$2:A$211,A5) -> 1 | C5: UIT-B | D5: 70-B3-D5-1F-31-AA-04-39 | E5: =VLOOKUP(D5,'Org Setup'!A:B,2,0) -> GS (1) | F5: =VLOOKUP(D5,'Org Setup'!A:D,4,0) -> 5.1 | G5: 44-11-02-00-00-29-03-58 | H5: H-DTAF-006-UB
A6: 690578100 | B6: =COUNTIF(A$2:A$211,A6) -> 1 | C6: UIT-A | D6: 70-B3-D5-1F-31-AA-03-39 | E6: =VLOOKUP(D6,'Org Setup'!A:B,2,0) -> GS (1) | F6: =VLOOKUP(D6,'Org Setup'!A:D,4,0) -> 5.1
A7: 689400109 | B7: =COUNTIF(A$2:A$211,A7) -> 1 | C7: UIT-A | D7: 70-B3-D5-1F-31-AA-03-39 | E7: =VLOOKUP(D7,'Org Setup'!A:B,2,0) -> GS (1) | F7: =VLOOKUP(D7,'Org Setup'!A:D,4,0) -> 5.1
A8: 688297003 | B8: =COUNTIF(A$2:A$211,A8) -> 1 | C8: UIT-A | D8: 70-B3-D5-1F-31-AA-03-39 | E8: =VLOOKUP(D8,'Org Setup'!A:B,2,0) -> GS (1) | F8: =VLOOKUP(D8,'Org Setup'!A:D,4,0) -> 5.1
A9: 687946907 | B9: =COUNTIF(A$2:A$211,A9) -> 1 | C9: UIT-A | D9: 70-B3-D5-1F-31-AA-03-39 | E9: =VLOOKUP(D9,'Org Setup'!A:B,2,0) -> GS (1) | F9: =VLOOKUP(D9,'Org Setup'!A:D,4,0) -> 5.1
A10: 686533405 | B10: =COUNTIF(A$2:A$211,A10) -> 1 | C10: UIT-A | D10: 70-B3-D5-1F-31-AA-03-39 | E10: =VLOOKUP(D10,'Org Setup'!A:B,2,0) -> GS (1) | F10: =VLOOKUP(D10,'Org Setup'!A:D,4,0) -> 5.1
A11: 685996407 | B11: =COUNTIF(A$2:A$211,A11) -> 1 | C11: UIT-A | D11: 70-B3-D5-1F-31-AA-03-39 | E11: =VLOOKUP(D11,'Org Setup'!A:B,2,0) -> GS (1) | F11: =VLOOKUP(D11,'Org Setup'!A:D,4,0) -> 5.1
A12: 681787007 | B12: =COUNTIF(A$2:A$211,A12) -> 1 | C12: UIT-A | D12: 70-B3-D5-1F-31-AA-03-39 | E12: =VLOOKUP(D12,'Org Setup'!A:B,2,0) -> GS (1) | F12: =VLOOKUP(D12,'Org Setup'!A:D,4,0) -> 5.1
A13: 681610607 | B13: =COUNTIF(A$2:A$211,A13) -> 1 | C13: UIT-A | D13: 70-B3-D5-1F-31-AA-03-39 | E13: =VLOOKUP(D13,'Org Setup'!A:B,2,0) -> GS (1) | F13: =VLOOKUP(D13,'Org Setup'!A:D,4,0) -> 5.1
A14: 680562707 | B14: =COUNTIF(A$2:A$211,A14) -> 1 | C14: UIT-A | D14: 70-B3-D5-1F-31-AA-03-39 | E14: =VLOOKUP(D14,'Org Setup'!A:B,2,0) -> GS (1) | F14: =VLOOKUP(D14,'Org Setup'!A:D,4,0) -> 5.1
A15: 678510307 | B15: =COUNTIF(A$2:A$211,A15) -> 1 | C15: UIT-A | D15: 70-B3-D5-1F-31-AA-03-39 | E15: =VLOOKUP(D15,'Org Setup'!A:B,2,0) -> GS (1) | F15: =VLOOKUP(D15,'Org Setup'!A:D,4,0) -> 5.1
A16: 676962007 | B16: =COUNTIF(A$2:A$211,A16) -> 1 | C16: UIT-A | D16: 70-B3-D5-1F-31-AA-03-39 | E16: =VLOOKUP(D16,'Org Setup'!A:B,2,0) -> GS (1) | F16: =VLOOKUP(D16,'Org Setup'!A:D,4,0) -> 5.1
A17: 676481608 | B17: =COUNTIF(A$2:A$211,A17) -> 1 | C17: UIT-A | D17: 70-B3-D5-1F-31-AA-03-39 | E17: =VLOOKUP(D17,'Org Setup'!A:B,2,0) -> GS (1) | F17: =VLOOKUP(D17,'Org Setup'!A:D,4,0) -> 5.1
... A38: 4213537101 | B38: =COUNTIF(A$2:A$211,A38) -> 1 | C38: UIT-A | D38: 70-B3-D5-1F-31-AA-03-39 | E38: =VLOOKUP(D38,'Org Setup'!A:B,2,0) -> GS (1) | F38: =VLOOKUP(D38,'Org Setup'!A:D,4,0) -> 5.1
A39: 4212302607 | B39: =COUNTIF(A$2:A$211,A39) -> 1 | C39: UIT-A | D39: 70-B3-D5-1F-31-AA-03-39 | E39: =VLOOKUP(D39,'Org Setup'!A:B,2,0) -> GS (1) | F39: =VLOOKUP(D39,'Org Setup'!A:D,4,0) -> 5.1 | G39: TLO - TAF test set
A40: 4208689402 | B40: =COUNTIF(A$2:A$211,A40) -> 1 | C40: UIT-A | D40: 70-B3-D5-1F-31-AA-03-39 | E40: =VLOOKUP(D40,'Org Setup'!A:B,2,0) -> GS (1) | F40: =VLOOKUP(D40,'Org Setup'!A:D,4,0) -> 5.1
A41: 4206397109 | B41: =COUNTIF(A$2:A$211,A41) -> 1 | C41: UIT-A | D41: 70-B3-D5-1F-31-AA-03-39 | E41: =VLOOKUP(D41,'Org Setup'!A:B,2,0) -> GS (1) | F41: =VLOOKUP(D41,'Org Setup'!A:D,4,0) -> 5.1
A42: 4204640800 | B42: =COUNTIF(A$2:A$211,A42) -> 1 | C42: UIT-A | D42: 70-B3-D5-1F-31-AA-03-39 | E42: =VLOOKUP(D42,'Org Setup'!A:B,2,0) -> GS (1) | F42: =VLOOKUP(D42,'Org Setup'!A:D,4,0) -> 5.1
A43: 4009769907 | B43: =COUNTIF(A$2:A$211,A43) -> 1 | C43: UIT-B | D43: 70-B3-D5-1F-31-AA-04-39 | E43: =VLOOKUP(D43,'Org Setup'!A:B,2,0) -> GS (1) | F43: =VLOOKUP(D43,'Org Setup'!A:D,4,0) -> 5.1 | G43: 98-B1-77-FF-FF-54-AA-EF | H43: H-DTAF-031-UB
A44: 3989042705 | B44: =COUNTIF(A$2:A$211,A44) -> 1 | C44: UIT-A | D44: 70-B3-D5-1F-31-AA-03-39 | E44: =VLOOKUP(D44,'Org Setup'!A:B,2,0) -> GS (1) | F44: =VLOOKUP(D44,'Org Setup'!A:D,4,0) -> 5.1
A45: 3981364507 | B45: =COUNTIF(A$2:A$211,A45) -> 1 | C45: UIT-A | D45: 70-B3-D5-1F-31-AA-03-39 | E45: =VLOOKUP(D45,'Org Setup'!A:B,2,0) -> GS (1) | F45: =VLOOKUP(D45,'Org Setup'!A:D,4,0) -> 5.1
A46: 3978844708 | B46: =COUNTIF(A$2:A$211,A46) -> 1 | C46: UIT-A | D46: 70-B3-D5-1F-31-AA-03-39 | E46: =VLOOKUP(D46,'Org Setup'!A:B,2,0) -> GS (1) | F46: =VLOOKUP(D46,'Org Setup'!A:D,4,0) -> 5.1
A47: 3977795402 | B47: =COUNTIF(A$2:A$211,A47) -> 1 | C47: UIT-A | D47: 70-B3-D5-1F-31-AA-03-39 | E47: =VLOOKUP(D47,'Org Setup'!A:B,2,0) -> GS (1) | F47: =VLOOKUP(D47,'Org Setup'!A:D,4,0) -> 5.1
A48: 3977204408 | B48: =COUNTIF(A$2:A$211,A48) -> 1 | C48: UIT-A | D48: 70-B3-D5-1F-31-AA-03-39 | E48: =VLOOKUP(D48,'Org Setup'!A:B,2,0) -> GS (1) | F48: =VLOOKUP(D48,'Org Setup'!A:D,4,0) -> 5.1
A49: 3245409606 | B49: =COUNTIF(A$2:A$211,A49) -> 1 | C49: UIT-A | D49: 70-B3-D5-1F-31-AA-03-39 | E49: =VLOOKUP(D49,'Org Setup'!A:B,2,0) -> GS (1) | F49: =VLOOKUP(D49,'Org Setup'!A:D,4,0) -> 5.1
A50: 3245128306 | B50: =COUNTIF(A$2:A$211,A50) -> 1 | C50: UIT-A | D50: 70-B3-D5-1F-31-AA-03-39 | E50: =VLOOKUP(D50,'Org Setup'!A:B,2,0) -> GS (1) | F50: =VLOOKUP(D50,'Org Setup'!A:D,4,0) -> 5.1
A51: 3244340400 | B51: =COUNTIF(A$2:A$211,A51) -> 1 | C51: UIT-A | D51: 70-B3-D5-1F-31-AA-03-39 | E51: =VLOOKUP(D51,'Org Setup'!A:B,2,0) -> GS (1) | F51: =VLOOKUP(D51,'Org Setup'!A:D,4,0) -> 5.1
A52: 3240002808 | B52: =COUNTIF(A$2:A$211,A52) -> 1 | C52: UIT-A | D52: 70-B3-D5-1F-31-AA-03-39 | E52: =VLOOKUP(D52,'Org Setup'!A:B,2,0) -> GS (1) | F52: =VLOOKUP(D52,'Org Setup'!A:D,4,0) -> 5.1
A53: 3235582805 | B53: =COUNTIF(A$2:A$211,A53) -> 1 | C53: UIT-A | D53: 70-B3-D5-1F-31-AA-03-39 | E53: =VLOOKUP(D53,'Org Setup'!A:B,2,0) -> GS (1) | F53: =VLOOKUP(D53,'Org Setup'!A:D,4,0) -> 5.1
A54: 3230407200 | B54: =COUNTIF(A$2:A$211,A54) -> 1 | C54: UIT-A | D54: 70-B3-D5-1F-31-AA-03-39 | E54: =VLOOKUP(D54,'Org Setup'!A:B,2,0) -> GS (1) | F54: =VLOOKUP(D54,'Org Setup'!A:D,4,0) -> 5.1
A55: 3230373007 | B55: =COUNTIF(A$2:A$211,A55) -> 1 | C55: UIT-A | D55: 70-B3-D5-1F-31-AA-03-39 | E55: =VLOOKUP(D55,'Org Setup'!A:B,2,0) -> GS (1) | F55: =VLOOKUP(D55,'Org Setup'!A:D,4,0) -> 5.1
A56: 2772178801 | B56: =COUNTIF(A$2:A$211,A56) -> 1 | C56: UIT-B | D56: 70-B3-D5-1F-31-AA-04-39 | E56: =VLOOKUP(D56,'Org Setup'!A:B,2,0) -> GS (1) | F56: =VLOOKUP(D56,'Org Setup'!A:D,4,0) -> 5.1
A57: 2772175705 | B57: =COUNTIF(A$2:A$211,A57) -> 1 | C57: UIT-B | D57: 70-B3-D5-1F-31-AA-04-39 | E57: =VLOOKUP(D57,'Org Setup'!A:B,2,0) -> GS (1) | F57: =VLOOKUP(D57,'Org Setup'!A:D,4,0) -> 5.1 | G57: 98-B1-77-FF-FF-62-12-FD | H57: H-DTAF-050-UB
A58: 2772174804 | B58: =COUNTIF(A$2:A$211,A58) -> 1 | C58: UIT-B | D58: 70-B3-D5-1F-31-AA-04-39 | E58: =VLOOKUP(D58,'Org Setup'!A:B,2,0) -> GS (1) | F58: =VLOOKUP(D58,'Org Setup'!A:D,4,0) -> 5.1 | G58: 44-11-02-00-00-2C-B9-0F | H58: H-DTAF-048-UB
A59: 2772174703 | B59: =COUNTIF(A$2:A$211,A59) -> 1 | C59: UIT-B | D59: 70-B3-D5-1F-31-AA-04-39 | E59: =VLOOKUP(D59,'Org Setup'!A:B,2,0) -> GS (1) | F59: =VLOOKUP(D59,'Org Setup'!A:D,4,0) -> 5.1 | G59: 44-11-02-00-00-20-ED-CB | H59: H-DTAF-004-UB
A60: 2772174108 | B60: =COUNTIF(A$2:A$211,A60) -> 1 | C60: UIT-B | D60: 70-B3-D5-1F-31-AA-04-39 | E60: =VLOOKUP(D60,'Org Setup'!A:B,2,0) -> GS (1) | F60: =VLOOKUP(D60,'Org Setup'!A:D,4,0) -> 5.1 | G60: 90-4D-C3-00-00-12-A5-16 | H60: H-DTAF-051-UB
...

Sheet URLs
A1: Status | B1: Environment | C1: Service Group | D1: Priority | E1: IP | F1: Port | G1: URL | H1: Use
A2: Working | B2: UIT-A (replicates to B) | C2: SMKI Portal | D2: Yes | E2: c.d.127.71 | G2: smki-org.uit.tsp.dccinterface.co.uk | H2: Organisation Subscriber Portal Landing Page (HTTPS - Server Side Authentication only)
A3: Working now | B3: UIT-A (replicates to B) | C3: SMKI Portal | D3: Yes | E3: c.d.127.71 | G3: smki-org-app.uit.tsp.dccinterface.co.uk | H3: Organisation Subscriber Portal Landing Page (HTTPS - Mutual Authentication using IKI)
A4: Working | B4: UIT-A (replicates to B) | C4: SMKI Portal | D4: Yes | E4: c.d.127.72 | G4: smki-device.uit.tsp.dccinterface.co.uk | H4: Device Subscriber Portal Landing page (HTTPS – Server Side Authentication only)
A5: Working now | B5: UIT-A (replicates to B) | C5: SMKI Portal | D5: Yes | E5: c.d.127.72 | G5: smki-device-app.uit.tsp.dccinterface.co.uk | H5: Device Subscriber Portal and Batch Device CSR web service (HTTPS – Mutual Authentication using IKI)
A6: Not working | B6: UIT-A (replicates to B) | C6: SMKI Portal | D6: Yes | E6: c.d.127.73 | G6: smki-s2s.uit.tsp.dccinterface.co.uk | H6: Ad Hoc Device CSR web service (HTPPS – Mutual Authentication using IKI)
A7: working after host file updated. will set up in AWS resolution. | B7: UIT-A | C7: SMKI Repo | D7: No | E7: a.b.40.67 | G7: smki-repo.uit.dsp.dccinterface.co.uk | H7: SMKI Repository web portal and web services (HTTPS – Server Side only)
A8: working after host file updated(port 80). will set up in AWS resolution. | B8: UIT-A | C8: SMKI Repo | D8: No | E8: a.b.40.67 | F8: 22 | G8: smki-repo.uit.dsp.dccinterface.co.uk | H8: SMKI Repository SFTP Interface
A9: working after host file updated. will set up in AWS resolution. need to check with credentials. | B9: UIT-A | C9: SMKI Repo | D9: No | E9: a.b.40.67 | G9: https://smki-repo.uit.dsp.dccinterface.co.uk/revocationlists/download/UA?apikey=<user_api_key> | H9: ARL
A10: working after host file updated. will set up in AWS resolution. need to check with credentials. | B10: UIT-A | C10: SMKI Repo | D10: No | E10: a.b.40.67 | G10: https://smki-repo.uit.dsp.dccinterface.co.uk/revocationlists/download/U1?apikey=<user_api_key> | H10: CRL
A11: working after host file updated. will set up in AWS resolution. | B11: UIT-A | C11: DCCKI Repo | D11: No | E11: a.b.40.75 | F11: 80 | G11: http://dccki-repo.mktp.dsp.dccinterface.co.uk/ | H11: DCCKI Certificate Repository
A12: Working | B12: UIT-B | C12: SMKI Repo | D12: Yes | E12: a.b.40.107 | G12: smki-repo.uitb.dsp.dccinterface.co.uk | H12: SMKI Repository web portal and web services (HTTPS – Server Side only)
A13: Connecting, but login userid, password not working | B13: UIT-B | C13: SMKI Repo | D13: Yes | E13: a.b.40.107 | F13: 22 | G13: smki-repo.uitb.dsp.dccinterface.co.uk | H13: SMKI Repository SFTP Interface
A14: Working | B14: UIT-B | C14: SMKI Repo | D14: Yes | E14: a.b.40.107 | G14: https://smki-repo.uitb.dsp.dccinterface.co.uk/revocationlists/download/UA?apikey=<user_api_key> | H14: ARL
A15: Working | B15: UIT-B | C15: SMKI Repo | D15: Yes | E15: a.b.40.107 | G15: https://smki-repo.uitb.dsp.dccinterface.co.uk/revocationlists/download/U1?apikey=<user_api_key> | H15: CRL
A16: Not working | B16: UIT-B | C16: DCCKI Repo | D16: Yes | E16: a.b.40.108 | F16: 80 | G16: http://dccki-repo.mktpc.dsp.dccinterface.co.uk | H16: DCCKI Certificate Repository
B17: UIT-A | C17: DCC User Interface (DUIS) | D17: No | E17: a.b.40.76 | F17: 443 | G17: https://msggw.uit.dsp.dccinterface.co.uk/mgs/execute/3.0 | H17: DCC Only Service
B18: UIT-A | C18: DCC User Interface (DUIS) | D18: No | E18: a.b.40.76 | F18: 443 | G18: https://msggw.uit.dsp.dccinterface.co.uk/mgs/transform/3.0 | H18: Transform Service
B19: UIT-A | C19: DCC User Interface (DUIS) | D19: No | E19: a.b.40.76 | F19: 443 | G19: https://msggw.uit.dsp.dccinterface.co.uk/mgs/deliver/3.0 | H19: Send Command Service
B20: UIT-A | C20: DCC User Interface (DUIS) | D20: No | E20: a.b.40.76 | F20: 443 | G20: https://msggw.uit.dsp.dccinterface.co.uk/mgs/execute/3.1 | H20: DCC Only Service
B21: UIT-A | C21: DCC User Interface (DUIS) | D21: No | E21: a.b.40.76 | F21: 443 | G21: https://msggw.uit.dsp.dccinterface.co.uk/mgs/transform/3.1 | H21: Transform Service
B22: UIT-A | C22: DCC User Interface (DUIS) | D22: No | E22: a.b.40.76 | F22: 443 | G22: https://msggw.uit.dsp.dccinterface.co.uk/mgs/deliver/3.1 | H22: Send Command Service
B23: UIT-A | C23: DCC User Interface (DUIS) | D23: No | E23: a.b.40.76 | F23: 443 | G23: https://msggw.uit.dsp.dccinterface.co.uk/mgs/execute/4.0 | H23: DCC Only Service
B24: UIT-A | C24: DCC User Interface (DUIS) | D24: No | E24: a.b.40.76 | F24: 443 | G24: https://msggw.uit.dsp.dccinterface.co.uk/mgs/transform/4.0 | H24: Transform Service
B25: UIT-A | C25: DCC User Interface (DUIS) | D25: No | E25: a.b.40.76 | F25: 443 | G25: https://msggw.uit.dsp.dccinterface.co.uk/mgs/deliver/4.0 | H25: Send Command Service
B26: UIT-A | C26: DCC User Interface (DUIS) | D26: No | E26: a.b.40.76 | F26: 443 | G26: https://msggw.uit.dsp.dccinterface.co.uk/mgs/execute/5.0 | H26: DCC Only Service
B27: UIT-A | C27: DCC User Interface (DUIS) | D27: No | E27: a.b.40.76 | F27: 443 | G27: https://msggw.uit.dsp.dccinterface.co.uk/mgs/transform/5.0 | H27: Transform Service
B28: UIT-A | C28: DCC User Interface (DUIS) | D28: No | E28: a.b.40.76 | F28: 443 | G28: https://msggw.uit.dsp.dccinterface.co.uk/mgs/deliver/5.0 | H28: Send Command Service
... B34: UIT-A | C34: DCC User Interface (DUIS) | D34: No | E34: a.b.40.76 | F34: 443 | G34: https://msggw.uit.dsp.dccinterface.co.uk/mgs/deliver/5.2 | H34: Send Command Service
B35: UIT-A | C35: DCC User Interface (DUIS) | D35: No | E35: a.b.40.101 | F35: 443 | H35: Receive Response Service
B36: UIT-B | C36: DCC User Interface (DUIS) | D36: Yes | E36: a.b.40.101 | F36: 443 | G36: https://msggw.uitb.dsp.dccinterface.co.uk/mgs/execute/3.0 | H36: DCC Only Service
B37: UIT-B | C37: DCC User Interface (DUIS) | D37: Yes | E37: a.b.40.101 | F37: 443 | G37: https://msggw.uitb.dsp.dccinterface.co.uk/mgs/transform/3.0 | H37: Transform Service
B38: UIT-B | C38: DCC User Interface (DUIS) | D38: Yes | E38: a.b.40.101 | F38: 443 | G38: https://msggw.uitb.dsp.dccinterface.co.uk/mgs/deliver/3.0 | H38: Send Command Service
B39: UIT-B | C39: DCC User Interface (DUIS) | D39: Yes | E39: a.b.40.101 | F39: 443 | G39: https://msggw.uitb.dsp.dccinterface.co.uk/mgs/execute/3.1 | H39: DCC Only Service
B40: UIT-B | C40: DCC User Interface (DUIS) | D40: Yes | E40: a.b.40.101 | F40: 443 | G40: https://msggw.uitb.dsp.dccinterface.co.uk/mgs/transform/3.1 | H40: Transform Service
B41: UIT-B | C41: DCC User Interface (DUIS) | D41: Yes | E41: a.b.40.101 | F41: 443 | G41: https://msggw.uitb.dsp.dccinterface.co.uk/mgs/deliver/3.1 | H41: Send Command Service
B42: UIT-B | C42: DCC User Interface (DUIS) | D42: Yes | E42: a.b.40.101 | F42: 443 | G42: https://msggw.uitb.dsp.dccinterface.co.uk/mgs/execute/4.0 | H42: DCC Only Service
B43: UIT-B | C43: DCC User Interface (DUIS) | D43: Yes | E43: a.b.40.101 | F43: 443 | G43: https://msggw.uitb.dsp.dccinterface.co.uk/mgs/transform/4.0 | H43: Transform Service
B44: UIT-B | C44: DCC User Interface (DUIS) | D44: Yes | E44: a.b.40.101 | F44: 443 | G44: https://msggw.uitb.dsp.dccinterface.co.uk/mgs/deliver/4.0 | H44: Send Command Service
B45: UIT-B | C45: DCC User Interface (DUIS) | D45: Yes | E45: a.b.40.101 | F45: 443 | G45: https://msggw.uitb.dsp.dccinterface.co.uk/mgs/execute/5.0 | H45: DCC Only Service
...

Sheet Registration Data Template
A1: EUI-64 | B1: Role | C1: DUIS Role | D1: DUIS Version | E1: Environment | F1: Determined Originator Name
A2: 70-B3-D5-1F-31-AA-03-00 | B2: Import Supplier 1 | C2: IS1 | D2: DUIS3.0 | E2: UIT-A | F2: =_xlfn.CONCAT(A2,"_",C2,"_",D2) -> 70-B3-D5-1F-31-AA-03-00_IS1_DUIS3.0
A3: 70-B3-D5-1F-31-AA-03-01 | B3: Import Supplier 2 | C3: IS2 | D3: DUIS3.0 | E3: UIT-A | F3: =_xlfn.CONCAT(A3,"_",C3,"_",D3) -> 70-B3-D5-1F-31-AA-03-01_IS2_DUIS3.0
A4: 70-B3-D5-1F-31-AA-03-02 | B4: Export Supplier | C4: ES | D4: DUIS3.0 | E4: UIT-A | F4: =_xlfn.CONCAT(A4,"_",C4,"_",D4) -> 70-B3-D5-1F-31-AA-03-02_ES_DUIS3.0
A5: 70-B3-D5-1F-31-AA-03-03 | B5: Gas Supplier 1 | C5: GS1 | D5: DUIS3.0 | E5: UIT-A | F5: =_xlfn.CONCAT(A5,"_",C5,"_",D5) -> 70-B3-D5-1F-31-AA-03-03_GS1_DUIS3.0
A6: 70-B3-D5-1F-31-AA-03-04 | B6: Gas Supplier 2 | C6: GS2 | D6: DUIS3.0 | E6: UIT-A | F6: =_xlfn.CONCAT(A6,"_",C6,"_",D6) -> 70-B3-D5-1F-31-AA-03-04_GS2_DUIS3.0
A7: 70-B3-D5-1F-31-AA-03-05 | B7: Electricity Distributor | C7: ED | D7: DUIS3.0 | E7: UIT-A | F7: =_xlfn.CONCAT(A7,"_",C7,"_",D7) -> 70-B3-D5-1F-31-AA-03-05_ED_DUIS3.0
A8: 70-B3-D5-1F-31-AA-03-06 | B8: Gas Transporter | C8: GT | D8: DUIS3.0 | E8: UIT-A | F8: =_xlfn.CONCAT(A8,"_",C8,"_",D8) -> 70-B3-D5-1F-31-AA-03-06_GT_DUIS3.0
A9: 70-B3-D5-1F-31-AA-03-07 | B9: Registered Supplier Agent | C9: RSA | D9: DUIS3.0 | E9: UIT-A | F9: =_xlfn.CONCAT(A9,"_",C9,"_",D9) -> 70-B3-D5-1F-31-AA-03-07_RSA_DUIS3.0
A10: 70-B3-D5-1F-31-AA-03-08 | B10: Other User | C10: OU | D10: DUIS3.0 | E10: UIT-A | F10: =_xlfn.CONCAT(A10,"_",C10,"_",D10) -> 70-B3-D5-1F-31-AA-03-08_OU_DUIS3.0
A11: 70-B3-D5-1F-31-AA-03-09 | B11: Import Supplier 1 | C11: IS1 | D11: DUIS3.1 | E11: UIT-A | F11: =_xlfn.CONCAT(A11,"_",C11,"_",D11) -> 70-B3-D5-1F-31-AA-03-09_IS1_DUIS3.1
A12: 70-B3-D5-1F-31-AA-03-10 | B12: Import Supplier 2 | C12: IS2 | D12: DUIS3.1 | E12: UIT-A | F12: =_xlfn.CONCAT(A12,"_",C12,"_",D12) -> 70-B3-D5-1F-31-AA-03-10_IS2_DUIS3.1
A13: 70-B3-D5-1F-31-AA-03-11 | B13: Export Supplier | C13: ES | D13: DUIS3.1 | E13: UIT-A | F13: =_xlfn.CONCAT(A13,"_",C13,"_",D13) -> 70-B3-D5-1F-31-AA-03-11_ES_DUIS3.1
... A257: 70-B3-D5-1F-31-AA-02-63 | B257: Meter Data Retriever | C257: MDR | D257: DUIS5.3 | E257: SIT-B | F257: =_xlfn.CONCAT(A257,"_",C257,"_",D257) -> 70-B3-D5-1F-31-AA-02-63_MDR_DUIS5.3

Sheet Org Cert Template
B1: DS | D1: KA | F1: PPKA | H1: XMLSign
B2: Remote Party Role Code (Organisational Unit) | C2: Common Name | D2: Remote Party Role Code (Organisational Unit) | E2: Common Name | F2: Remote Party Role Code (Organisational Unit) | G2: Common Name | H2: Remote Party Role Code (Organisational Unit) | I2: Common Name
A3: Import Supplier | B3: 02 | C3: Import Supplier "x" | D3: 02 | E3: Import Supplier "x" | F3: 02 | G3: Import Supplier "x" | H3: 87 | I3: HCLT
A4: Gas Supplier | B4: 02 | C4: Gas Supplier "x" | D4: 02 | E4: Gas Supplier "x" | F4: 02 | G4: Gas Supplier "x" | H4: 87 | I4: HCL
A5: Export Supplier | B5: 02 | C5: Export Supplier | D5: 02 | E5: Export Supplier | F5: N/A | G5: Export Supplier | H5: 87 | I5: HCLT
A6: Electricity Distributor | B6: 03 | C6: Electricity Distributor | D6: 03 | E6: Electricity Distributor | F6: N/A | G6: Electricity Distributor | H6: 87 | I6: HCLT
A7: Gas Transporter | B7: 03 | C7: Gas Transporter | D7: 03 | E7: Gas Transporter | F7: N/A | G7: Gas Transporter | H7: 87 | I7: HCL
A8: Registered Supplier Agent | B8: NA | C8: Registered Supplier Agent | D8: 7F | E8: Registered Supplier Agent | F8: N/A | G8: Registered Supplier Agent | H8: 87 | I8: HCLT HCL
A9: Other User | B9: NA | C9: Other User | D9: 7F | E9: Other User | F9: N/A | G9: Other User | H9: 87 | I9: HCLT HCL
A10: Meter Data Retriever | B10: NA | C10: Meter Data Retriever | D10: 7F | E10: Meter Data Retriever | F10: N/A | G10: Meter Data Retriever | H10: 87 | I10: HCLT HCL
B12: Subject Common Name - see SEC Appendix B - "Organisation Certificate Profile" Note - we've chosen to ignore the rules around population of "Common Name" as SMKI doesn't prevent it, it's useful to include and doesn't seem to impact any Device Behaviour.
